<?xml version="1.0"?>
<robot name="robot_name">
    <link name="base_link">
        <visual>
            <origin xyz="0.0 0.0 0.0" rpy="0.0 0.0 0.0"/>
            <geometry>
                <box size="0.2 0.2 0.1"/>
            </geometry>
            <material name="yellow">
                <color rgba="0.7 0.7 0.1 0.30"/>
            </material>
        </visual>
        <collision>
            <origin xyz="0.0 0.0 0.0" rpy="0.0 0.0 0.0"/>
            <geometry>
                <box size="0.2 0.2 0.1"/>
            </geometry>
        </collision>
    </link>

    <link name="brazo">
        <visual>
            <origin xyz="0.0 0.0 0.2" rpy="0.0 0.0 0.0"/>
            <geometry>
                <cylinder radius="0.05" length="0.4"/>
            </geometry>
            <material name="red">
                <color rgba="0.9 0.1 0.1 0.50"/>
            </material>
        </visual>
        <collision>
            <origin xyz="0.0 0.0 0.2" rpy="0.0 0.0 0.0"/>
            <geometry>
                <cylinder radius="0.05" length="0.4"/>
            </geometry>
        </collision>
    </link>

    <joint name="base_brazo_joint" type="revolute">
        <parent link="base_link"/>
        <child link="brazo"/>
        <origin xyz="0.0 0.0 0.05" rpy="0.0 0.0 0.0"/>
        <axis xyz="0.0 -1 0.0"/>
        <limit lower="${-pi/2}" upper="${pi/2}" effort="100" velocity="100"/>
    </joint>
</robot>