<?xml version="1.0"?>
<robot name="differential-robot">
    <link name="base_link">
        <visual>
            <origin xyz="0.0 0.0 0.15" rpy="0.0 0.0 0.0"/>
            <geometry>
                <box size="0.5 0.25 0.1"/>
            </geometry>
        </visual>
        <collision>
            <origin xyz="0.0 0.0 0.15" rpy="0.0 0.0 0.0"/>
            <geometry>
                <box size="0.5 0.25 0.1"/>
            </geometry>
        </collision>
    </link>

    <link name="left_wheel">
        <visual>
            <origin xyz="0.0 0.0 0.0" rpy="${pi/2} 0.0 0.0"/>
            <geometry>
                <cylinder radius="0.1" length="0.05"/>
            </geometry>
        </visual>
        <collision>
            <origin xyz="0.0 0.0 0.0" rpy="${pi/2} 0.0 0.0"/>
            <geometry>
                <cylinder radius="0.1" length="0.05"/>
            </geometry>
        </collision>
    </link>

    <link name="right_wheel">
        <visual>
            <origin xyz="0.0 0.0 0.0" rpy="${pi/2} 0.0 0.0"/>
            <geometry>
                <cylinder radius="0.1" length="0.05"/>
            </geometry>
        </visual>
        <collision>
            <origin xyz="0.0 0.0 0.0" rpy="${pi/2} 0.0 0.0"/>
            <geometry>
                <cylinder radius="0.1" length="0.05"/>
            </geometry>
        </collision>
    </link>

    <link name="caster_wheel">
        <visual>
            <origin xyz="0.0 0.0 0.0" rpy="0.0 0.0 0.0"/>
            <geometry>
                <sphere radius="0.05"/>
            </geometry>
        </visual>
        <collision>
            <origin xyz="0.0 0.0 0.0" rpy="0.0 0.0 0.0"/>
            <geometry>
                <sphere radius="0.05"/>
            </geometry>
        </collision>
    </link>

    <joint name="base_link_left_wheel_joint" type="continuous">
        <parent link="base_link"/>
        <child link="left_wheel"/>
        <origin xyz="0.2 -0.125 0.1" rpy="${-pi} 0.0 0.0"/>
        <axis xyz="0.0 1 0.0"/>
    </joint>  

    <joint name="base_link_right_wheel_joint" type="continuous">
        <parent link="base_link"/>
        <child link="right_wheel"/>
        <origin xyz="0.2 0.125 0.1" rpy="0.0 0.0 0.0"/>
        <axis xyz="0.0 1 0.0"/>
    </joint>    

    <joint name="base_link_caster_wheel_joint" type="fixed">
        <parent link="base_link"/>
        <child link="caster_wheel"/>
        <origin xyz="-0.2 0.0 0.1" rpy="0.0 0.0 0.0"/>
        
    </joint>
    
</robot>