<?xml version="1.0" ?>
<!-- =================================================================================== -->
<!-- |    This document was autogenerated by xacro from demo_simulation3/urdf/robot-core.urdf | -->
<!-- |    EDITING THIS FILE BY HAND IS NOT RECOMMENDED                                 | -->
<!-- =================================================================================== -->
<robot name="robot">
  <!-- Robot Link -->
  <link name="base_link">
    <visual>
      <origin rpy="0 0 0" xyz="0 0 0.09"/>
      <geometry>
        <box size="0.42 0.31 0.18"/>
      </geometry>
      <material name="Cyan">
        <color rgba="0 1.0 1.0 1.0"/>
      </material>
    </visual>
    <collision>
      <origin rpy="0 0 0" xyz="0 0 0.09"/>
      <geometry>
        <box size="0.42 0.31 0.18"/>
      </geometry>
    </collision>
    <inertial>
      <origin rpy="1.5707963267948966 0 1.5707963267948966" xyz="0 0 0"/>
      <mass value="5"/>
      <inertia ixx="0.087" ixy="0.0" ixz="0.0" iyy="0.11354166666666665" iyz="0.0" izz="0.05354166666666667"/>
    </inertial>
  </link>
  <gazebo reference="base_lin">
    <material>Gazebo/Orange</material>
  </gazebo>
  <!-- Caster Wheel -->
  <link name="caster">
    <visual>
      <geometry>
        <sphere radius="0.01"/>
      </geometry>
      <material name="white">
        <color rgba="1 1.0 1.0 1.0"/>
      </material>
    </visual>
    <collision>
      <origin rpy="0 0 0" xyz="0 0 0"/>
      <geometry>
        <sphere radius="0.01"/>
      </geometry>
    </collision>
    <inertial>
      <mass value="0.5"/>
      <inertia ixx="8.000000000000005e-05" ixy="0.0" ixz="0.0" iyy="8.000000000000005e-05" iyz="0.0" izz="8.000000000000005e-05"/>
    </inertial>
  </link>
  <gazebo reference="caster">
    <material>Gazebo/Blue</material>
    <mu1 value="0.001"/>
    <mu2 value="0.001"/>
  </gazebo>
  <joint name="caster_joint" type="fixed">
    <parent link="base_link"/>
    <child link="caster"/>
    <origin rpy="0 0 0" xyz="-0.1 0.0 0"/>
  </joint>
  <link name="drivewhl_l_link">
    <visual>
      <origin rpy="1.5707963267948966 0 0" xyz="0 0 0"/>
      <geometry>
        <cylinder length="0.04" radius="0.1"/>
      </geometry>
      <material name="Gray">
        <color rgba="0.5 0.5 0.5 1.0"/>
      </material>
    </visual>
    <collision>
      <origin rpy="1.5707963267948966 0 0" xyz="0 0 0"/>
      <geometry>
        <cylinder length="0.04" radius="0.1"/>
      </geometry>
    </collision>
    <inertial>
      <origin rpy="1.5707963267948966 0 0" xyz="0 0 0"/>
      <mass value="0.5"/>
      <inertia ixx="0.0013166666666666667" ixy="0" ixz="0" iyy="0.0013166666666666667" iyz="0" izz="0.0025000000000000005"/>
    </inertial>
  </link>
  <joint name="drivewhl_l_joint" type="continuous">
    <parent link="base_link"/>
    <child link="drivewhl_l_link"/>
    <origin rpy="0 0 0" xyz="0.05 0.18 0.09000000000000001"/>
    <axis xyz="0 1 0"/>
  </joint>
  <link name="drivewhl_r_link">
    <visual>
      <origin rpy="1.5707963267948966 0 0" xyz="0 0 0"/>
      <geometry>
        <cylinder length="0.04" radius="0.1"/>
      </geometry>
      <material name="Gray">
        <color rgba="0.5 0.5 0.5 1.0"/>
      </material>
    </visual>
    <collision>
      <origin rpy="1.5707963267948966 0 0" xyz="0 0 0"/>
      <geometry>
        <cylinder length="0.04" radius="0.1"/>
      </geometry>
    </collision>
    <inertial>
      <origin rpy="1.5707963267948966 0 0" xyz="0 0 0"/>
      <mass value="0.5"/>
      <inertia ixx="0.0013166666666666667" ixy="0" ixz="0" iyy="0.0013166666666666667" iyz="0" izz="0.0025000000000000005"/>
    </inertial>
  </link>
  <joint name="drivewhl_r_joint" type="continuous">
    <parent link="base_link"/>
    <child link="drivewhl_r_link"/>
    <origin rpy="0 0 0" xyz="0.05 -0.18 0.09000000000000001"/>
    <axis xyz="0 1 0"/>
  </joint>
  <gazebo>
    <plugin filename="libgazebo_ros_diff_drive.so" name="diff_drive">
      <!-- wheels -->
      <left_joint>drivewhl_l_joint</left_joint>
      <right_joint>drivewhl_r_joint</right_joint>
      <!-- kinematics -->
      <wheel_separation>0.4</wheel_separation>
      <wheel_diameter>0.2</wheel_diameter>
      <!-- limits -->
      <max_wheel_torque>200</max_wheel_torque>
      <max_wheel_acceleration>10.0</max_wheel_acceleration>
      <!-- output -->
      <odometry_frame>odom</odometry_frame>
      <robot_base_frame>base_link</robot_base_frame>
      <publish_odom>true</publish_odom>
      <publish_odom_tf>true</publish_odom_tf>
      <publish_wheel_tf>true</publish_wheel_tf>
    </plugin>
  </gazebo>
</robot>
